<?xml version="1.0" encoding="utf-8"?>
<!-- This URDF was automatically created by SolidWorks to URDF Exporter! Originally created by Stephen Brawner (brawner@gmail.com) 
     Commit Version: 1.6.0-4-g7f85cfe  Build Version: 1.6.7995.38578
     For more information, please see http://wiki.ros.org/sw_urdf_exporter -->
<robot
  name="vacuum_robot" 
  xmlns:xacro="http://www.ros.org/wiki/xacro">
  
<!-- Import Rviz colors -->
<xacro:include filename="$(find vacuum_robot)/urdf/materials.xacro" />

<!-- Import all Gazebo-customization elements, including Gazebo colors -->
  <xacro:include filename="$(find vacuum_robot)/urdf/mybot.gazebo" />


 <!--dummy link-->
        <link name="base_footprint"/>
        <joint name="dummy_joint" type="fixed">
          <origin xyz="0.0 0.0 0.0" rpy="0.0 0.0 0.0"/>
          <parent link="base_footprint"/>
          <child link="base_link"/>
          <axis xyz="0.0 0.0 0.0"/>
          <limit lower="0.0" upper="0.0" effort="0.0" velocity="0.0"/>
        </joint>

  <link
    name="base_link">
    <inertial>
      <origin
        xyz="0.001167 -0.00017905 0.0177"
        rpy="0 0 0" />
      <mass
        value="0.33739" />
      <inertia
        ixx="0.0028468"
        ixy="6.2586E-10"
        ixz="1.4453E-06"
        iyy="0.0028585"
        iyz="2.2404E-09"
        izz="0.0053109" />
    </inertial>
    <visual>
      <origin
        xyz="0 0 0"
        rpy="0 0 0" />
      <geometry>
        <mesh
          filename="package://vacuum_robot/meshes/base_link.STL" />
      </geometry>
      <material
        name="">
        <color
          rgba="0.79216 0.81961 0.93333 1" />
      </material>
    </visual>
    <collision>
      <origin
        xyz="0 0 0"
        rpy="0 0 0" />
      <geometry>
        <mesh
          filename="package://vacuum_robot/meshes/base_link.STL" />
      </geometry>
    </collision>
  </link>

  <link
    name="RightUltra_link">
    <inertial>
      <origin
        xyz="-0.00059247 -0.14853 0.040053"
        rpy="0 0 0" />
      <mass
        value="0.0062273" />
      <inertia
        ixx="2.3852E-07"
        ixy="1.3189E-10"
        ixz="1.9966E-10"
        iyy="1.2204E-06"
        iyz="2.0237E-09"
        izz="1.1941E-06" />
    </inertial>
    <visual>
      <origin
        xyz="0 0 0"
        rpy="0 0 0" />
      <geometry>
        <mesh
          filename="package://vacuum_robot/meshes/RightUltra_link.STL" />
      </geometry>
      <material
        name="">
        <color
          rgba="0.79216 0.81961 0.93333 1" />
      </material>
    </visual>
    <collision>
      <origin
        xyz="0 0 0"
        rpy="0 0 0" />
      <geometry>
        <mesh
          filename="package://vacuum_robot/meshes/RightUltra_link.STL" />
      </geometry>
    </collision>
  </link>

  <joint
    name="RightUltra_joint"
    type="fixed">
    <origin
      xyz="0 0 0"
      rpy="0 0 0" />
    <parent
      link="base_link" />
    <child
      link="RightUltra_link" />
    <axis
      xyz="0 0 0" />
  </joint>

  <link
    name="FrontUltra_link">
    <inertial>
      <origin
        xyz="0.1477 -0.00018295 0.040053"
        rpy="0 0 0" />
      <mass
        value="0.0062273" />
      <inertia
        ixx="1.2204E-06"
        ixy="-1.3189E-10"
        ixz="-2.0237E-09"
        iyy="2.3852E-07"
        iyz="1.9966E-10"
        izz="1.1941E-06" />
    </inertial>
    <visual>
      <origin
        xyz="0 0 0"
        rpy="0 0 0" />
      <geometry>
        <mesh
          filename="package://vacuum_robot/meshes/FrontUltra_link.STL" />
      </geometry>
      <material
        name="">
        <color
          rgba="0.79216 0.81961 0.93333 1" />
      </material>
    </visual>
    <collision>
      <origin
        xyz="0 0 0"
        rpy="0 0 0" />
      <geometry>
        <mesh
          filename="package://vacuum_robot/meshes/FrontUltra_link.STL" />
      </geometry>
    </collision>
  </link>

  <joint
    name="FrontUltra_joint"
    type="fixed">
    <origin
      xyz="0 0 0"
      rpy="0 0 0" />
    <parent
      link="base_link" />
    <child
      link="FrontUltra_link" />
    <axis
      xyz="0 0 0" />
  </joint>

  <link
    name="LeftUltra_link">
    <inertial>
      <origin
        xyz="-0.00058406 0.14846 0.040053"
        rpy="0 0 0" />
      <mass
        value="0.0062273" />
      <inertia
        ixx="2.3852E-07"
        ixy="1.3189E-10"
        ixz="-1.9966E-10"
        iyy="1.2204E-06"
        iyz="-2.0237E-09"
        izz="1.1941E-06" />
    </inertial>
    <visual>
      <origin
        xyz="0 0 0"
        rpy="0 0 0" />
      <geometry>
        <mesh
          filename="package://vacuum_robot/meshes/LeftUltra_link.STL" />
      </geometry>
      <material
        name="">
        <color
          rgba="0.79216 0.81961 0.93333 1" />
      </material>
    </visual>
    <collision>
      <origin
        xyz="0 0 0"
        rpy="0 0 0" />
      <geometry>
        <mesh
          filename="package://vacuum_robot/meshes/LeftUltra_link.STL" />
      </geometry>
    </collision>
  </link>

  <joint
    name="LeftUltra_joint"
    type="fixed">
    <origin
      xyz="0 0 0"
      rpy="0 0 0" />
    <parent
      link="base_link" />
    <child
      link="LeftUltra_link" />
    <axis
      xyz="0 0 0" />
  </joint>
  <link
    name="CasterWheel_link">
    <inertial>
      <origin
        xyz="0.074308 -7.4627E-05 -0.0057749"
        rpy="0 0 0" />
      <mass
        value="0.0066846" />
      <inertia
        ixx="4.665E-07"
        ixy="1.9714E-22"
        ixz="-3.4365E-25"
        iyy="4.665E-07"
        iyz="-7.5675E-24"
        izz="8.8561E-07" />
    </inertial>
    <visual>
      <origin
        xyz="0 0 0"
        rpy="0 0 0" />
      <geometry>
        <mesh
          filename="package://vacuum_robot/meshes/CasterWheel_link.STL" />
      </geometry>
      <material
        name="">
        <color
          rgba="0.79216 0.81961 0.93333 1" />
      </material>
    </visual>
    <collision>
      <origin
        xyz="0 0 0"
        rpy="0 0 0" />
      <geometry>
        <mesh
          filename="package://vacuum_robot/meshes/CasterWheel_link.STL" />
      </geometry>
    </collision>
  </link>

  <joint
    name="CasterWheel_joint"
    type="fixed">
    <origin
      xyz="0 0 0"
      rpy="0 0 0" />
    <parent
      link="base_link" />
    <child
      link="CasterWheel_link" />
    <axis
      xyz="0 0 0" />
  </joint>
  <link
    name="RightWheel_link">
    <inertial>
      <origin
        xyz="-4.7552E-11 -0.015624 7.2047E-11"
        rpy="0 0 0" />
      <mass
        value="0.30664" />
      <inertia
        ixx="0.00012023"
        ixy="6.996E-14"
        ixz="-1.216E-13"
        iyy="0.0002214"
        iyz="-6.3898E-14"
        izz="0.00012023" />
    </inertial>
    <visual>
      <origin
        xyz="0 0 0"
        rpy="0 0 0" />
      <geometry>
        <mesh
          filename="package://vacuum_robot/meshes/RightWheel_link.STL" />
      </geometry>
      <material
        name="">
        <color
          rgba="0.65098 0.61961 0.58824 1" />
      </material>
    </visual>
    <collision>
      <origin
        xyz="0 0 0"
        rpy="0 0 0" />
      <geometry>
        <mesh
          filename="package://vacuum_robot/meshes/RightWheel_link.STL" />
      </geometry>
    </collision>
  </link>

  <joint
    name="RightWheel_joint"
    type="continuous">
    <origin
      xyz="-0.047803 -0.071097 0.014931"
      rpy="0 0 0" />
    <parent
      link="base_link" />
    <child
      link="RightWheel_link" />
    <axis
      xyz="0.014195 -0.99982 -0.012697" />
    <limit
      effort="3"
      velocity="3" />
  </joint>

  <link
    name="LeftWheel_link">
    <inertial>
      <origin
        xyz="-4.7554E-11 0.015624 -7.2047E-11"
        rpy="0 0 0" />
      <mass
        value="0.30664" />
      <inertia
        ixx="0.00012023"
        ixy="-6.9962E-14"
        ixz="1.216E-13"
        iyy="0.0002214"
        iyz="-6.3898E-14"
        izz="0.00012023" />
    </inertial>
    <visual>
      <origin
        xyz="0 0 0"
        rpy="0 0 0" />
      <geometry>
        <mesh
          filename="package://vacuum_robot/meshes/LeftWheel_link.STL" />
      </geometry>
      <material
        name="">
        <color
          rgba="0.65098 0.61961 0.58824 1" />
      </material>
    </visual>
    <collision>
      <origin
        xyz="0 0 0"
        rpy="0 0 0" />
      <geometry>
        <mesh
          filename="package://vacuum_robot/meshes/LeftWheel_link.STL" />
      </geometry>
    </collision>
  </link>

  <joint
    name="LeftWheel_Joint"
    type="continuous">
    <origin
      xyz="-0.047803 0.070646 0.014931"
      rpy="0 0 0" />
    <parent
      link="base_link" />
    <child
      link="LeftWheel_link" />
    <axis
      xyz="0.014195 -0.99982 -0.012697" />
    <limit
      effort="3"
      velocity="3" />
  </joint>

  <link
    name="Cover_link">
    <inertial>
      <origin
        xyz="0.001167 -0.00017905 0.0177"
        rpy="0 0 0" />
      <mass
        value="0.33739" />
      <inertia
        ixx="0.0028468"
        ixy="6.2586E-10"
        ixz="1.4453E-06"
        iyy="0.0028585"
        iyz="2.2404E-09"
        izz="0.0053109" />
    </inertial>
    <visual>
      <origin
        xyz="0 0 0"
        rpy="0 0 0" />
      <geometry>
        <mesh
          filename="package://vacuum_robot/meshes/Cover_link.STL" />
      </geometry>
      <material
        name="">
        <color
          rgba="0.79216 0.81961 0.93333 1" />
      </material>
    </visual>
    <collision>
      <origin
        xyz="0 0 0"
        rpy="0 0 0" />
      <geometry>
        <mesh
          filename="package://vacuum_robot/meshes/Cover_link.STL" />
      </geometry>
    </collision>
  </link>

  <joint
    name="Cover_joint"
    type="fixed">
    <origin
      xyz="0 0 0"
      rpy="0 0 0" />
    <parent
      link="base_link" />
    <child
      link="Cover_link" />
    <axis
      xyz="0 0 0" />
  </joint>

  <link
    name="Lidar_link">
    <inertial>
      <origin
        xyz="-2.0817E-17 4.7184E-15 0.098458"
        rpy="0 0 0" />
      <mass
        value="0.17056" />
      <inertia
        ixx="8.0287E-05"
        ixy="9.209E-38"
        ixz="-1.7995E-37"
        iyy="8.0287E-05"
        iyz="3.0477E-23"
        izz="0.00012075" />
    </inertial>
    <visual>
      <origin
        xyz="0 0 -0.1"
        rpy="0 0 0" />
      <geometry>
        <mesh
          filename="package://vacuum_robot/meshes/Lidar_link.STL" />
      </geometry>
      <material
        name="">
        <color
          rgba="0.79216 0.81961 0.93333 1" />
      </material>
    </visual>
    <collision>
      <origin
        xyz="0 0 -0.1"
        rpy="0 0 0" />
      <geometry>
        <mesh
          filename="package://vacuum_robot/meshes/Lidar_link.STL" />
      </geometry>
    </collision>
  </link>

  <joint
    name="Lidar_joint"
    type="fixed">
    <origin
      xyz="0 0 0.1"
      rpy="0 0 0" />
    <parent
      link="Cover_link" />
    <child
      link="Lidar_link" />
    <axis
      xyz="0 0 0" />
  </joint>
</robot>